input.dat
4294966295,U,B,2,0.996,4
4294966296,I,S,0,1.009,3
4294966296,I,S,0,1.008,1
4294966297,D,S,3,1.012,2
4294966298,I,B,0,1.001,10
4294966299,U,B,2,0.998,3
4294966299,D,S,4,1.015,7
4294966300,I,S,3,1.013,8
4294966301,D,B,1,1.000,1
4294966301,D,S,0,1.008,1
4294966302,U,S,4,1.015,7
4294966303,U,B,4,0.993,6
4294966304,I,S,0,1.008,6
4294966305,D,B,3,0.994,4
4294966305,U,S,2,1.010,2
4294966306,U,B,0,1.001,9
4294966307,U,S,2,1.010,1
4294966308,D,S,4,1.014,3
4294966309,U,S,0,1.008,7
4294966310,D,S,0,1.008,7
4294966311,D,S,0,1.009,3
4294966311,D,S,0,1.010,1
4294966312,I,B,0,1.002,1
4294966312,I,B,0,1.003,4
4294966313,D,B,4,0.996,4
4294966314,D,B,4,0.995,3
4294966315,I,B,0,1.004,1
4294966316,D,B,0,1.004,1
4294966316,I,S,0,1.012,2
4294966317,U,S,4,1.017,2
4294966318,D,B,0,1.003,4
4294966318,D,B,0,1.002,1
4294966319,I,S,0,1.011,1
4294966319,I,S,0,1.010,9
4294966320,I,S,0,1.009,7
4294966321,I,S,0,1.008,8
4294966321,I,S,0,1.007,1
4294966322,D,B,0,1.001,9
4294966322,D,B,0,0.998,3
4294966323,U,S,0,1.007,2
4294966324,D,S,0,1.007,2
4294966324,I,B,0,0.998,6
4294966325,D,B,0,0.998,6
4294966325,D,B,0,0.997,5
4294966326,D,B,3,0.993,10
4294966327,U,B,0,0.996,7
4294966328,I,B,3,0.993,5
4294966329,U,S,2,1.010,8
4294966330,I,S,0,1.007,2
4294966330,I,S,0,1.006,8
4294966331,I,S,0,1.005,9
4294966331,I,S,0,1.004,7
4294966332,U,S,0,1.004,8
4294966333,U,B,1,0.995,10
4294966334,U,B,3,0.993,6
4294966335,I,B,0,0.997,8
4294966336,D,S,2,1.006,8
4294966337,I,S,0,1.003,2
4294966338,D,S,0,1.003,2
4294966339,I,S,0,1.003,5
4294966340,U,B,1,0.996,8
4294966341,I,S,0,1.002,4
4294966342,I,B,0,0.998,8
4294966343,I,S,0,1.001,8
4294966343,I,S,0,1.000,10
4294966344,D,B,1,0.997,8
4294966345,D,S,2,1.002,4
4294966346,I,S,2,1.002,8
4294966347,U,S,0,1.000,9
4294966348,D,B,0,0.998,8
4294966348,D,B,0,0.996,8
4294966349,I,B,0,0.996,2
4294966350,D,B,0,0.996,2
4294966350,D,B,0,0.995,10
4294966351,I,B,0,0.995,1
4294966352,D,B,2,0.993,10
4294966353,I,B,0,0.996,1
4294966353,I,B,0,0.997,8
4294966354,D,B,0,0.997,8
4294966354,D,B,0,0.996,1
4294966355,U,B,2,0.992,9
4294966356,D,B,0,0.995,1
4294966356,D,B,0,0.994,10
4294966357,D,B,0,0.992,9
4294966358,U,B,1,0.990,1
4294966359,U,S,1,1.001,9
4294966360,I,B,0,0.992,2
4294966360,I,B,0,0.993,1
4294966361,I,S,0,0.999,8
4294966361,I,S,0,0.998,3
4294966362,D,B,0,0.993,1
4294966362,D,B,0,0.992,2
4294966363,I,B,0,0.992,6
4294966364,U,S,1,0.999,7
4294966365,I,S,0,0.997,3
4294966366,U,S,1,0.998,4
4294966367,U,B,1,0.991,9
4294966368,U,B,3,0.989,11
4294966369,U,B,0,0.992,5
4294966370,I,S,0,0.996,10
4294966370,I,S,0,0.995,8
4294966371,I,S,0,0.994,5
4294966371,I,S,0,0.993,6
4294966372,U,S,0,0.993,7
4294966373,D,B,0,0.992,5
4294966374,U,S,1,0.994,4
4294966375,D,S,0,0.993,7
4294966375,D,S,0,0.994,4
4294966376,D,S,2,0.997,3
4294966377,U,B,4,0.987,5
4294966378,D,S,0,0.995,8
4294966378,D,S,0,0.996,10
4294966379,U,S,3,1.001,10
4294966380,D,B,0,0.991,9
4294966380,D,B,0,0.990,1
4294966381,U,S,0,0.998,8
4294966382,I,S,0,0.997,8
4294966383,U,B,2,0.987,4
4294966384,I,S,0,0.996,2
4294966384,I,S,0,0.995,10
4294966385,D,S,0,0.995,10
4294966385,I,B,0,0.990,3
4294966386,D,B,0,0.990,3
4294966386,D,B,0,0.989,11
4294966387,D,B,2,0.986,4
4294966388,I,S,0,0.995,2
4294966388,I,S,0,0.994,3
4294966389,D,S,2,0.996,2
4294966390,I,S,0,0.993,10
4294966390,I,S,0,0.992,5
4294966391,D,S,0,0.992,5
4294966391,D,S,0,0.993,10
4294966392,I,B,0,0.989,2
4294966393,I,S,0,0.993,5
4294966393,I,S,0,0.992,3
4294966394,I,S,0,0.991,4
4294966394,I,S,0,0.990,7
4294966395,I,B,3,0.986,3
4294966396,U,S,2,0.992,4
4294966397,U,S,0,0.990,8
4294966398,U,S,2,0.992,3
4294966399,D,B,0,0.989,2
4294966399,D,B,0,0.988,1
4294966400,D,B,0,0.987,4
4294966401,I,B,0,0.987,8
4294966402,I,S,0,0.989,5
4294966402,I,S,0,0.988,7
4294966403,D,S,0,0.988,7
4294966403,I,B,0,0.988,10
4294966404,D,B,0,0.988,10
4294966404,D,B,0,0.987,8
4294966405,D,S,0,0.989,5
4294966406,D,B,0,0.986,3
4294966407,D,S,0,0.990,8
4294966407,D,S,0,0.991,4
4294966408,I,B,0,0.986,8
4294966409,D,S,0,0.992,3
4294966409,I,B,0,0.987,7
4294966410,D,B,0,0.987,7
4294966410,D,B,0,0.986,8
4294966411,D,B,4,0.981,8
4294966412,I,S,0,0.992,8
4294966413,U,S,4,0.996,3
4294966414,I,B,0,0.986,8
4294966415,I,S,0,0.991,4
4294966416,D,B,0,0.986,8
4294966417,I,B,0,0.986,4
4294966418,D,S,0,0.991,4
4294966418,D,S,0,0.992,8
4294966419,U,S,4,0.997,6
4294966420,D,S,0,0.993,9
4294966421,I,S,0,0.993,8
4294966421,I,S,0,0.992,2
4294966422,U,S,0,0.992,3
4294966423,U,S,4,0.996,4
4294966424,I,B,0,0.987,2
4294966424,I,B,0,0.988,4
4294966425,I,B,0,0.989,7
4294966426,D,S,1,0.993,8
4294966427,D,B,0,0.989,7
4294966427,I,S,0,0.991,3
4294966428,D,B,0,0.988,4
4294966428,I,S,0,0.990,6
4294966429,I,S,3,0.993,10
4294966430,I,B,0,0.988,7
4294966431,D,S,2,0.992,3
4294966432,D,B,0,0.988,7
4294966433,D,S,3,0.994,2
4294966434,D,B,0,0.987,2
4294966434,D,B,0,0.986,4
4294966435,I,B,0,0.986,7
4294966436,D,S,0,0.990,6
4294966436,D,S,0,0.991,3
4294966437,I,B,0,0.987,10
4294966438,U,S,2,0.996,7
4294966439,I,B,0,0.988,10
4294966439,I,B,0,0.989,4
4294966440,D,S,0,0.993,10
4294966441,D,B,0,0.989,4
4294966441,D,B,0,0.988,10
4294966442,D,S,0,0.995,10
4294966442,I,B,0,0.988,6
4294966443,D,S,2,0.998,6
4294966444,I,S,0,0.995,6
4294966444,I,S,0,0.994,3
4294966445,I,S,0,0.993,10
4294966446,D,S,0,0.993,10
4294966446,I,B,0,0.989,10
4294966447,D,B,0,0.989,10
4294966447,D,B,0,0.988,6
4294966448,D,B,0,0.987,10
4294966449,U,B,0,0.986,6
4294966450,U,B,0,0.986,7
4294966451,I,S,0,0.993,8
4294966452,D,S,0,0.993,8
4294966452,D,S,0,0.994,3
4294966453,I,B,0,0.987,4
4294966454,I,S,0,0.994,5
4294966455,I,S,0,0.993,2
4294966456,I,S,0,0.992,3
4294966457,U,S,3,0.995,7
4294966458,D,S,3,0.995,7
4294966459,I,S,0,0.991,7
4294966459,I,S,0,0.990,8
4294966460,D,S,1,0.991,7
4294966461,I,S,0,0.989,5
4294966462,I,B,0,0.988,8
4294966463,D,B,0,0.988,8
4294966463,D,B,0,0.987,4
4294966464,D,S,0,0.989,5
4294966465,I,B,0,0.987,7
4294966465,I,B,0,0.988,9
4294966466,U,B,4,0.984,2
4294966467,U,B,0,0.988,8
4294966468,D,S,0,0.990,8
4294966469,D,S,2,0.994,5
4294966470,U,S,0,0.992,2
4294966471,D,S,0,0.992,2
4294966471,I,B,0,0.989,2
4294966472,U,B,3,0.986,6
4294966473,I,S,0,0.992,3
4294966473,I,S,0,0.991,3
4294966474,D,B,1,0.988,8
4294966475,D,S,0,0.991,3
4294966475,I,B,0,0.990,7
4294966476,D,B,4,0.985,3
4294966477,I,B,0,0.991,3
4294966478,D,B,0,0.991,3
4294966478,D,B,0,0.990,7
4294966479,U,S,4,0.997,11
4294966480,D,S,0,0.992,3
4294966481,I,B,1,0.988,5
4294966482,D,B,0,0.989,2
4294966483,I,S,0,0.992,9
4294966484,D,S,0,0.992,9
4294966484,D,S,0,0.993,2
4294966485,I,S,0,0.994,1
4294966486,D,S,3,0.997,11
4294966487,D,S,0,0.994,1
4294966488,D,B,0,0.988,5
4294966489,D,B,1,0.986,6
4294966490,I,B,1,0.986,8
4294966491,D,S,0,0.995,2
4294966492,D,B,4,0.983,6
4294966493,U,S,0,0.996,9
4294966494,I,B,0,0.988,6
4294966494,I,B,0,0.989,7
4294966495,D,S,4,1.001,1
4294966496,D,B,0,0.989,7
4294966497,I,B,0,0.989,10
4294966497,I,B,0,0.990,9
4294966498,U,B,0,0.990,8
4294966499,U,S,0,0.996,10
4294966500,D,S,0,0.996,10
4294966500,D,S,0,0.998,7
4294966501,I,B,0,0.991,1
4294966502,U,S,1,1.000,1
4294966503,U,S,3,1.003,8
4294966504,I,S,0,0.998,9
4294966505,D,B,0,0.991,1
4294966506,D,S,1,0.999,7
4294966507,D,S,0,0.998,9
4294966507,D,S,0,1.000,1
4294966508,I,B,0,0.991,7
4294966508,I,B,0,0.992,3
4294966509,U,S,1,1.003,7
4294966510,U,B,2,0.990,7
4294966511,D,S,3,1.005,7
4294966512,I,B,0,0.993,10
4294966512,I,B,0,0.994,3
4294966513,U,B,2,0.992,4
4294966514,U,B,0,0.994,4
4294966515,D,B,0,0.994,4
4294966516,D,S,1,1.003,7
4294966517,D,B,4,0.989,7
4294966518,U,S,0,1.002,11
4294966519,U,B,0,0.993,9
4294966520,U,B,0,0.993,8
4294966521,U,S,1,1.004,8
4294966522,D,S,0,1.002,11
4294966523,D,B,4,0.988,8
4294966524,U,S,2,1.007,2
4294966525,U,S,0,1.004,9
4294966526,I,B,0,0.994,10
4294966526,I,B,0,0.995,1
4294966527,U,S,0,1.004,10
4294966528,I,B,0,0.996,7
4294966528,I,B,0,0.997,5
4294966529,U,B,0,0.997,4
4294966530,D,B,1,0.996,7
4294966531,I,B,0,0.998,7
4294966531,I,B,0,0.999,10
4294966532,U,S,2,1.007,1
4294966533,I,S,0,1.003,1
4294966534,I,S,0,1.002,3
4294966534,I,S,0,1.001,8
4294966535,I,B,0,1.000,4
4294966536,U,S,1,1.002,4
4294966537,D,B,3,0.997,4
