input_short.dat
4294966295,U,B,2,0.996,4
4294966296,I,S,0,1.009,3
4294966296,I,S,0,1.008,1
4294966297,D,S,3,1.012,2
4294966298,I,B,0,1.001,10
4294966299,U,B,2,0.998,3
4294966299,D,S,4,1.015,7
4294966300,I,S,3,1.013,8
4294966301,D,B,1,1.000,1
4294966301,D,S,0,1.008,1
